{"name": "test_get_all_test_suites_exception", "status": "passed", "description": "Test retrieval of all test suites with an exception caused by the API.", "attachments": [{"name": "log", "source": "aaef6593-71f5-41fa-abe3-d60797cfea80-attachment.txt", "type": "text/plain"}], "start": 1743499569874, "stop": 1743499569875, "uuid": "6ee447e4-a985-48d3-8cf2-e43339d9b798", "historyId": "fc07bc7ff31acdc49e93ffc8d9f5495e", "testCaseId": "fc07bc7ff31acdc49e93ffc8d9f5495e", "fullName": "src.tests.ado.test_plan.test_unit_ado_test_plan.TestPlanApiWrapperNegative#test_get_all_test_suites_exception", "labels": [{"name": "tag", "value": "negative"}, {"name": "tag", "value": "ado_test_plan"}, {"name": "tag", "value": "unit"}, {"name": "parentSuite", "value": "src.tests.ado.test_plan"}, {"name": "suite", "value": "test_unit_ado_test_plan"}, {"name": "subSuite", "value": "TestPlanApiWrapperNegative"}, {"name": "host", "value": "fv-az1120-17"}, {"name": "thread", "value": "2592-MainThread"}, {"name": "framework", "value": "pytest"}, {"name": "language", "value": "cpython3"}, {"name": "package", "value": "src.tests.ado.test_plan.test_unit_ado_test_plan"}]}