{"name": "test_add_test_case_logs_error", "status": "passed", "description": "Test logger called when addition of test cases fails.", "start": 1743504726555, "stop": 1743504726556, "uuid": "b15a44d4-86ff-46a4-99bd-c1ebde0c706f", "historyId": "14a2ea932e5d2d538f59e40733927f7e", "testCaseId": "14a2ea932e5d2d538f59e40733927f7e", "fullName": "src.tests.ado.test_plan.test_unit_ado_test_plan.TestPlanApiWrapperExceptions#test_add_test_case_logs_error", "labels": [{"name": "tag", "value": "exception_handling"}, {"name": "tag", "value": "ado_test_plan"}, {"name": "tag", "value": "unit"}, {"name": "parentSuite", "value": "src.tests.ado.test_plan"}, {"name": "suite", "value": "test_unit_ado_test_plan"}, {"name": "subSuite", "value": "TestPlanApiWrapperExceptions"}, {"name": "host", "value": "fv-az1927-746"}, {"name": "thread", "value": "2344-MainThread"}, {"name": "framework", "value": "pytest"}, {"name": "language", "value": "cpython3"}, {"name": "package", "value": "src.tests.ado.test_plan.test_unit_ado_test_plan"}]}