{"name": "test_get_test_case_invalid", "status": "passed", "description": "Test retrieval with an error caused by the API.", "attachments": [{"name": "log", "source": "3aed5649-2289-4e67-9b8e-a2d88123fbe4-attachment.txt", "type": "text/plain"}], "start": 1743504726435, "stop": 1743504726436, "uuid": "c39acca0-a5c4-4ee7-9d0e-0bb381441d40", "historyId": "1770d75ee88316b20b505555e260487c", "testCaseId": "1770d75ee88316b20b505555e260487c", "fullName": "src.tests.ado.test_plan.test_unit_ado_test_plan.TestPlanApiWrapperNegative#test_get_test_case_invalid", "labels": [{"name": "tag", "value": "negative"}, {"name": "tag", "value": "ado_test_plan"}, {"name": "tag", "value": "unit"}, {"name": "parentSuite", "value": "src.tests.ado.test_plan"}, {"name": "suite", "value": "test_unit_ado_test_plan"}, {"name": "subSuite", "value": "TestPlanApiWrapperNegative"}, {"name": "host", "value": "fv-az1927-746"}, {"name": "thread", "value": "2344-MainThread"}, {"name": "framework", "value": "pytest"}, {"name": "language", "value": "cpython3"}, {"name": "package", "value": "src.tests.ado.test_plan.test_unit_ado_test_plan"}]}