{"name": "test_run_raises_tool_exception", "status": "passed", "description": "Test that _run catches an exception and returns a ToolException.", "start": 1743501667872, "stop": 1743501667872, "uuid": "ba7c54c5-dba9-4cf7-8138-2d067cb675fd", "historyId": "8d1eecec13ed794897fb24f5a596568f", "testCaseId": "8d1eecec13ed794897fb24f5a596568f", "fullName": "src.tests.test_base_tool.TestBaseAction#test_run_raises_tool_exception", "labels": [{"name": "tag", "value": "negative"}, {"name": "tag", "value": "base"}, {"name": "tag", "value": "unit"}, {"name": "parentSuite", "value": "src.tests"}, {"name": "suite", "value": "test_base_tool"}, {"name": "subSuite", "value": "TestBaseAction"}, {"name": "host", "value": "fv-az2032-69"}, {"name": "thread", "value": "2321-MainThread"}, {"name": "framework", "value": "pytest"}, {"name": "language", "value": "cpython3"}, {"name": "package", "value": "src.tests.test_base_tool"}]}