{"name": "test_get_test_suite_exception", "status": "passed", "description": "Test retrieval with an exception caused by the API.", "attachments": [{"name": "log", "source": "289af0d7-861a-43e1-8085-cf36972ca14b-attachment.txt", "type": "text/plain"}], "start": 1743505054895, "stop": 1743505054895, "uuid": "dd912c7e-002d-4219-937a-9f163631b256", "historyId": "f94de1422cb3d7ae4746b5a46b3f693e", "testCaseId": "f94de1422cb3d7ae4746b5a46b3f693e", "fullName": "src.tests.ado.test_plan.test_unit_ado_test_plan.TestPlanApiWrapperNegative#test_get_test_suite_exception", "labels": [{"name": "tag", "value": "negative"}, {"name": "tag", "value": "ado_test_plan"}, {"name": "tag", "value": "unit"}, {"name": "parentSuite", "value": "src.tests.ado.test_plan"}, {"name": "suite", "value": "test_unit_ado_test_plan"}, {"name": "subSuite", "value": "TestPlanApiWrapperNegative"}, {"name": "host", "value": "fv-az1673-369"}, {"name": "thread", "value": "2350-MainThread"}, {"name": "framework", "value": "pytest"}, {"name": "language", "value": "cpython3"}, {"name": "package", "value": "src.tests.ado.test_plan.test_unit_ado_test_plan"}]}